Workbook

Sheet Overview
A1: Opening: The Granular Financial Breakdown
A2: Scaled personnel costs and partner budgets prepared for Erasmus+ internal planning and portal-ready audit checks.
A5: Partner | B5: Personnel (€) | C5: Subcontracting (€) | D5: Travel (€) | E5: Equipment (€) | F5: Other Goods (€) | G5: Indirect (€) | H5: Total Budget (€)
A6: UNIVERSITY OF MALTA (UM) | B6: 178607.48 | C6: 15000 | D6: 10000 | E6: 2000 | F6: 15000 | G6: 14392.52 | H6: =SUM(B6:G6) -> 235000
A7: HUMBOLDT-UNIVERSITÄT ZU BERLIN (UBER) | B7: 172177.57 | C7: 0 | D7: 6000 | E7: 1000 | F7: 4000 | G7: 12822.43 | H7: =SUM(B7:G7) -> 196000
A8: ELLINOGERMANIKI AGOGI (EA) | B8: 128859.81 | C8: 0 | D8: 8000 | E8: 3000 | F8: 5000 | G8: 10140.19 | H8: =SUM(B8:G8) -> 155000
A9: MALTA FURTHER AND HIGHER EDUCATION AUTHORITY (MFHEA) | B9: 120102.81 | C9: 0 | D9: 7000 | E9: 0 | F9: 0 | G9: 8897.19 | H9: =SUM(B9:G9) -> 136000
A10: CHAMBER OF COMMERCE, INDUSTRY AND SERVICES OF TERRASSA (CCIT) | B10: 150224.3 | C10: 0 | D10: 8000 | E10: 0 | F10: 10000 | G10: 11775.7 | H10: =SUM(B10:G10) -> 180000
A11: T2 S.R.L. | B11: 142532.71 | C11: 0 | D11: 7000 | E11: 0 | F11: 0 | G11: 10467.29 | H11: =SUM(B11:G11) -> 160000
A12: LITHUANIAN UNIVERSITY OF HEALTH SCIENCES (LSMU) | B12: 167700.93 | C12: 0 | D12: 6000 | E12: 0 | F12: 2000 | G12: 12299.07 | H12: =SUM(B12:G12) -> 188000
A13: Consortium Total | B13: =SUM(B6:B12) -> 1060205.6 | C13: =SUM(C6:C12) -> 15000 | D13: =SUM(D6:D12) -> 52000 | E13: =SUM(E6:E12) -> 6000 | F13: =SUM(F6:F12) -> 36000 | G13: =SUM(G6:G12) -> 80794.39 | H13: =SUM(H6:H12) -> 1250000

Sheet Partner_Detail
A1: Partner Personnel and Other Eligible Costs
A2: Personnel rows are followed by other-cost rows; the Checks sheet validates all partner totals.
A4: Partner | B4: Work Package | C4: Entry Type | D4: Item | E4: Role / Description | F4: Monthly Rate (€) | G4: Adjusted PMs | H4: Cost (€)
A5: UNIVERSITY OF MALTA (UM) | B5: Coordinator (WP1) | C5: Personnel | D5: Prof. Matthew Montebello | E5: Project Coordinator | F5: 7232.93 | G5: 10.3 | H5: 74499.18
A6: UNIVERSITY OF MALTA (UM) | B6: Coordinator (WP1) | C6: Personnel | D6: Dr. Vanessa Camilleri | E6: Senior Researcher | F6: 5112.52 | G6: 12.87 | H6: 65808.35
A7: UNIVERSITY OF MALTA (UM) | B7: Coordinator (WP1) | C7: Personnel | D7: Research Support Officer | E7: RSO II - Project Manager | F7: 2976.6 | G7: 12.86 | H7: 38299.95
A8: UNIVERSITY OF MALTA (UM) | B8: Coordinator (WP1) | C8: Other Cost | D8: Subcontracting | E8: Subcontracting | H8: 15000
A9: UNIVERSITY OF MALTA (UM) | B9: Coordinator (WP1) | C9: Other Cost | D9: Travel | E9: Travel | H9: 10000
A10: UNIVERSITY OF MALTA (UM) | B10: Coordinator (WP1) | C10: Other Cost | D10: Equipment | E10: Equipment | H10: 2000
A11: UNIVERSITY OF MALTA (UM) | B11: Coordinator (WP1) | C11: Other Cost | D11: Other Goods | E11: Other Goods | H11: 15000
A12: UNIVERSITY OF MALTA (UM) | B12: Coordinator (WP1) | C12: Other Cost | D12: Indirect | E12: Indirect | H12: 14392.52
A13: HUMBOLDT-UNIVERSITÄT ZU BERLIN (UBER) | B13: WP3/WP4 | C13: Personnel | D13: Prof. Dr. Rüdiger Tiemann | E13: Scientific Director / Pedagogical Lead | F13: 8800 | G13: 5 | H13: 44000
A14: HUMBOLDT-UNIVERSITÄT ZU BERLIN (UBER) | B14: WP3/WP4 | C14: Personnel | D14: Smita Singh | E14: Researcher / Scientific Co-worker, TV-L E13 scaled | F14: 7495 | G14: 17.1 | H14: 128177.57
A15: HUMBOLDT-UNIVERSITÄT ZU BERLIN (UBER) | B15: WP3/WP4 | C15: Other Cost | D15: Subcontracting | E15: Subcontracting | H15: 0
A16: HUMBOLDT-UNIVERSITÄT ZU BERLIN (UBER) | B16: WP3/WP4 | C16: Other Cost | D16: Travel | E16: Travel | H16: 6000
A17: HUMBOLDT-UNIVERSITÄT ZU BERLIN (UBER) | B17: WP3/WP4 | C17: Other Cost | D17: Equipment | E17: Equipment | H17: 1000
A18: HUMBOLDT-UNIVERSITÄT ZU BERLIN (UBER) | B18: WP3/WP4 | C18: Other Cost | D18: Other Goods | E18: Other Goods | H18: 4000
A19: HUMBOLDT-UNIVERSITÄT ZU BERLIN (UBER) | B19: WP3/WP4 | C19: Other Cost | D19: Indirect | E19: Indirect | H19: 12822.43
A20: ELLINOGERMANIKI AGOGI (EA) | B20: WP4 | C20: Personnel | D20: Dr. Sofoklis Sotiriou | E20: Head of R&D | F20: 5000 | G20: 2.8 | H20: 14000
A21: ELLINOGERMANIKI AGOGI (EA) | B21: WP4 | C21: Personnel | D21: Nikos Zygouritsas | E21: Project Manager / Living Lab Coordinator | F21: 5000 | G21: 8.6 | H21: 43000
A22: ELLINOGERMANIKI AGOGI (EA) | B22: WP4 | C22: Personnel | D22: Dimitra Dimitrakopoulou | E22: ICT Teacher / Pedagogical Integration | F22: 5000 | G22: 7.2 | H22: 36000
A23: ELLINOGERMANIKI AGOGI (EA) | B23: WP4 | C23: Personnel | D23: Dimitris Koulentianos | E23: Researcher / AI Data Evaluation | F23: 5000 | G23: 7.17 | H23: 35859.81
A24: ELLINOGERMANIKI AGOGI (EA) | B24: WP4 | C24: Other Cost | D24: Subcontracting | E24: Subcontracting | H24: 0
A25: ELLINOGERMANIKI AGOGI (EA) | B25: WP4 | C25: Other Cost | D25: Travel | E25: Travel | H25: 8000
A26: ELLINOGERMANIKI AGOGI (EA) | B26: WP4 | C26: Other Cost | D26: Equipment | E26: Equipment | H26: 3000
A27: ELLINOGERMANIKI AGOGI (EA) | B27: WP4 | C27: Other Cost | D27: Other Goods | E27: Other Goods | H27: 5000
A28: ELLINOGERMANIKI AGOGI (EA) | B28: WP4 | C28: Other Cost | D28: Indirect | E28: Indirect | H28: 10140.19
A29: MALTA FURTHER AND HIGHER EDUCATION AUTHORITY (MFHEA) | B29: WP2 | C29: Personnel | D29: Dr. Jana Kazarjan | E29: Senior Researcher / Policy Senior Manager | F29: 3136 | G29: 10.7 | H29: 33555.2
A30: MALTA FURTHER AND HIGHER EDUCATION AUTHORITY (MFHEA) | B30: WP2 | C30: Personnel | D30: Jessica Sammut | E30: Researcher / Policy Officer | F30: 3136 | G30: 9.2 | H30: 28851.2
A31: MALTA FURTHER AND HIGHER EDUCATION AUTHORITY (MFHEA) | B31: WP2 | C31: Personnel | D31: Ryan Saliba | E31: Researcher / Policy Officer | F31: 3136 | G31: 9.2 | H31: 28851.2
A32: MALTA FURTHER AND HIGHER EDUCATION AUTHORITY (MFHEA) | B32: WP2 | C32: Personnel | D32: Kamen Gechev | E32: Researcher / Policy Officer | F32: 3136 | G32: 9.2 | H32: 28845.21
A33: MALTA FURTHER AND HIGHER EDUCATION AUTHORITY (MFHEA) | B33: WP2 | C33: Other Cost | D33: Subcontracting | E33: Subcontracting | H33: 0
A34: MALTA FURTHER AND HIGHER EDUCATION AUTHORITY (MFHEA) | B34: WP2 | C34: Other Cost | D34: Travel | E34: Travel | H34: 7000
A35: MALTA FURTHER AND HIGHER EDUCATION AUTHORITY (MFHEA) | B35: WP2 | C35: Other Cost | D35: Equipment | E35: Equipment | H35: 0
A36: MALTA FURTHER AND HIGHER EDUCATION AUTHORITY (MFHEA) | B36: WP2 | C36: Other Cost | D36: Other Goods | E36: Other Goods | H36: 0
A37: MALTA FURTHER AND HIGHER EDUCATION AUTHORITY (MFHEA) | B37: WP2 | C37: Other Cost | D37: Indirect | E37: Indirect | H37: 8897.19
A38: CHAMBER OF COMMERCE, INDUSTRY AND SERVICES OF TERRASSA (CCIT) | B38: WP5 | C38: Personnel | D38: Josep Prats | E38: Managing Director / Senior Expert | F38: 6000 | G38: 2.8 | H38: 16800
A39: CHAMBER OF COMMERCE, INDUSTRY AND SERVICES OF TERRASSA (CCIT) | B39: WP5 | C39: Personnel | D39: Julia Puerta | E39: Project Manager / WP5 Coordinator | F39: 6000 | G39: 8.35 | H39: 50100
A40: CHAMBER OF COMMERCE, INDUSTRY AND SERVICES OF TERRASSA (CCIT) | B40: WP5 | C40: Personnel | D40: Alba Cabeza | E40: Head of Digital Transformation | F40: 6000 | G40: 6.94 | H40: 41640
A41: CHAMBER OF COMMERCE, INDUSTRY AND SERVICES OF TERRASSA (CCIT) | B41: WP5 | C41: Personnel | D41: Sonia Perez | E41: Training Service Manager | F41: 6000 | G41: 6.94 | H41: 41684.3
...

Sheet Checks
A1: Audit Controls
A2: All control variances should resolve to zero after formula recalculation.
A4: Partner | B4: Stated Budget (€) | C4: Calculated Detail Total (€) | D4: Variance (€) | E4: Check Type | F4: Threshold (€) | G4: Status
A5: UNIVERSITY OF MALTA (UM) | B5: 235000 | C5: =SUMIF(Partner_Detail!$A:$A,A5,Partner_Detail!$H:$H) -> 235000 | D5: =B5-C5 -> 0 | E5: Partner | F5: 0.01 | G5: =IF(ABS(D5)<0.01,"OK","CHECK") -> OK
A6: HUMBOLDT-UNIVERSITÄT ZU BERLIN (UBER) | B6: 196000 | C6: =SUMIF(Partner_Detail!$A:$A,A6,Partner_Detail!$H:$H) -> 196000 | D6: =B6-C6 -> 0 | E6: Partner | F6: 0.01 | G6: =IF(ABS(D6)<0.01,"OK","CHECK") -> OK
A7: ELLINOGERMANIKI AGOGI (EA) | B7: 155000 | C7: =SUMIF(Partner_Detail!$A:$A,A7,Partner_Detail!$H:$H) -> 155000 | D7: =B7-C7 -> 0 | E7: Partner | F7: 0.01 | G7: =IF(ABS(D7)<0.01,"OK","CHECK") -> OK
A8: MALTA FURTHER AND HIGHER EDUCATION AUTHORITY (MFHEA) | B8: 136000 | C8: =SUMIF(Partner_Detail!$A:$A,A8,Partner_Detail!$H:$H) -> 136000 | D8: =B8-C8 -> 0 | E8: Partner | F8: 0.01 | G8: =IF(ABS(D8)<0.01,"OK","CHECK") -> OK
A9: CHAMBER OF COMMERCE, INDUSTRY AND SERVICES OF TERRASSA (CCIT) | B9: 180000 | C9: =SUMIF(Partner_Detail!$A:$A,A9,Partner_Detail!$H:$H) -> 180000 | D9: =B9-C9 -> 0 | E9: Partner | F9: 0.01 | G9: =IF(ABS(D9)<0.01,"OK","CHECK") -> OK
A10: T2 S.R.L. | B10: 160000 | C10: =SUMIF(Partner_Detail!$A:$A,A10,Partner_Detail!$H:$H) -> 160000 | D10: =B10-C10 -> 0 | E10: Partner | F10: 0.01 | G10: =IF(ABS(D10)<0.01,"OK","CHECK") -> OK
A11: LITHUANIAN UNIVERSITY OF HEALTH SCIENCES (LSMU) | B11: 188000 | C11: =SUMIF(Partner_Detail!$A:$A,A11,Partner_Detail!$H:$H) -> 188000 | D11: =B11-C11 -> 0 | E11: Partner | F11: 0.01 | G11: =IF(ABS(D11)<0.01,"OK","CHECK") -> OK
A13: Consortium Total | B13: 1250000 | C13: =SUM(C5:C11) -> 1250000 | D13: =B13-C13 -> 0 | E13: Consortium | F13: 0.01 | G13: =IF(ABS(D13)<0.01,"OK","CHECK") -> OK
